Workbook

Sheet Dashboard
A1: COMPONENT QC INSPECTION — QUALITY DASHBOARD
B2: Lab Sensor & Sistem Telekontrol (SSTK) | Dept. Teknik Nuklir & Teknik Fisika, UGM | 4 Praktikum | ~80 Mahasiswa/Minggu | All values auto-calculated
B4: Pass Rate Elektronika Analog | D4: Pass Rate Elektronika Digital | H4: Pass Rate Sistem Instrumentasi | J4: Pass Rate Jaringan Komunikasi
B6: =IFERROR(Elek_Analog!I66/Elek_Analog!H66,0) -> 0.875 | D6: =IFERROR(Elek_Digital!I66/Elek_Digital!H66,0) -> 0.70833333 | H6: =IFERROR(Sistem_Instr!I66/Sistem_Instr!H66,0) -> 0.8125 | J6: =IFERROR(Jar_Komunikasi!I66/Jar_Komunikasi!H66,0) -> 0.625
B10: ▶ CROSS-PRACTICUM INSPECTION SUMMARY
B11: Practikum | C11: Total Inspected | D11: Total PASS | G11: Top Defect Count
B12: Elektronika Analog | C12: =Elek_Analog!H66 -> 48 | D12: =Elek_Analog!I66 -> 42 | E12: =Elek_Analog!J66 -> 6 | F12: =IFERROR(Elek_Analog!I66/Elek_Analog!H66,0) -> 0.875 | G12: =Elek_Analog!J66 -> 6
B13: Elektronika Digital | C13: =Elek_Digital!H66 -> 48 | D13: =Elek_Digital!I66 -> 34 | E13: =Elek_Digital!J66 -> 14 | F13: =IFERROR(Elek_Digital!I66/Elek_Digital!H66,0) -> 0.70833333 | G13: =Elek_Digital!J66 -> 14
B14: Sistem Instrumentasi | C14: =Sistem_Instr!H66 -> 48 | D14: =Sistem_Instr!I66 -> 39 | E14: =Sistem_Instr!J66 -> 9 | F14: =IFERROR(Sistem_Instr!I66/Sistem_Instr!H66,0) -> 0.8125 | G14: =Sistem_Instr!J66 -> 9
B15: Jaringan Komunikasi | C15: =Jar_Komunikasi!H66 -> 48 | D15: =Jar_Komunikasi!I66 -> 30 | E15: =Jar_Komunikasi!J66 -> 18 | F15: =IFERROR(Jar_Komunikasi!I66/Jar_Komunikasi!H66,0) -> 0.625 | G15: =Jar_Komunikasi!J66 -> 18
B16: TOTAL ALL PRACTIKUM | C16: =SUM(C12:C15) -> 192 | D16: =SUM(D12:D15) -> 145 | E16: =SUM(E12:E15) -> 47 | F16: =IFERROR(D16/C16,0) -> 0.75520833
A19: 📋 FORMULA & CALCULATION NOTES — DASHBOARD FORMULA NOTES
A20: Column / Field | B20: Calculation Logic
A21: KPI Cards — Pass Rate | B21: [Formula] (relay_pass + switch_pass) / (relay_total + switch_total) | G21: AUTO. Pulls PASS and total counts from each practikum sheet's summary row. Updates automatically when new inspection data is added.
A22: Summary Table — Pass Rate | B22: [Formula] pass_count / total_inspected per practikum | G22: AUTO. Per-practikum pass rate from each inspection log summary. All 4 values feed into the cross-practikum bar chart.
A23: Summary Table — Total/PASS/FAIL | B23: [Formula] direct reference to practikum sheet summary row | G23: AUTO. Values sourced directly from summary formulas in each inspection sheet. No manual input required on this sheet.
A24: Bar Chart — Pass Rate by Practikum | B24: References Summary Table Col F (Pass Rate) | G24: AUTO-updated chart. Bars reflect current pass rates from all 4 practikum inspection logs. Provides at-a-glance comparison of quality across practikum types.
A25: ℹ Dashboard requires zero manual input. All values auto-calculated from the 4 practikum inspection sheets. Refresh Excel or open file to recalculate.

Sheet Elek_Analog
A1: PRAKTIKUM ELEKTRONIKA ANALOG — COMPONENT QC INSPECTION LOG
A2: Lab Sensor & Sistem Telekontrol (SSTK) | Dept. Teknik Nuklir & Teknik Fisika, UGM | ~20 Mahasiswa/Sesi
A3: Test Equipment: Multimeter (Sanwa CD771), LCR Meter, Oscilloscope (GDS-1022), DC Power Supply
A5: No. | B5: Part Number | C5: Component Description | D5: Batch / Lot No. | E5: Inspection Date | F5: Qty | G5: Visual Inspection | H5: Spec / Rated Value | I5: Measured Value | J5: Functional Test 1 | K5: Test 1 Result | L5: Functional Test 2 | M5: Test 2 Result | N5: Overall Result | O5: Remarks / Disposition
A6: ⚠ Columns shaded yellow = manual input per inspection session | Columns shaded gray = auto-calculated by formula | Overall Result = auto (PASS only if ALL tests pass)
A7: Inspection Session: Sesi A — Week 1 | Batch: LOT-A-2024
A8: 1 | B8: R-10kΩ-CFR | C8: Resistor 10kΩ | D8: LOT-A-581 | E8: 05-Apr-2026 | F8: 24 | G8: Pass | H8: 10 | I8: 10.19 | J8: Measured Value | K8: =IF(G8="Fail","Fail",IF(ABS(I8-H8)/IF(H8=0,1,H8)<=0.1,"Pass","Fail")) -> Pass | L8: Tolerance | M8: Pass | N8: =IF(AND(G8="Pass",K8="Pass",M8="Pass"),"PASS","FAIL") -> PASS | O8: =IF(N8="PASS","Release to practicum","Quarantine — do not issue to students") -> Release to practicum
A9: 2 | B9: R-1kΩ-CFR | C9: Resistor 1kΩ | D9: LOT-A-875 | E9: 05-Apr-2026 | F9: 25 | G9: Pass | H9: 1 | I9: 0.94 | J9: Measured Value | K9: =IF(G9="Fail","Fail",IF(ABS(I9-H9)/IF(H9=0,1,H9)<=0.1,"Pass","Fail")) -> Pass | L9: Tolerance | M9: Pass | N9: =IF(AND(G9="Pass",K9="Pass",M9="Pass"),"PASS","FAIL") -> PASS | O9: =IF(N9="PASS","Release to practicum","Quarantine — do not issue to students") -> Release to practicum
A10: 3 | B10: C-100µF-EC | C10: Capacitor 100µF | D10: LOT-A-462 | E10: 05-Apr-2026 | F10: 22 | G10: Pass | H10: 100 | I10: 105.47 | J10: Measured Cap | K10: =IF(G10="Fail","Fail",IF(ABS(I10-H10)/IF(H10=0,1,H10)<=0.1,"Pass","Fail")) -> Pass | L10: ESR Test | M10: Pass | N10: =IF(AND(G10="Pass",K10="Pass",M10="Pass"),"PASS","FAIL") -> PASS | O10: =IF(N10="PASS","Release to practicum","Quarantine — do not issue to students") -> Release to practicum
A11: 4 | B11: C-10nF-MLC | C11: Capacitor 10nF | D11: LOT-A-656 | E11: 05-Apr-2026 | F11: 21 | G11: Pass | H11: 10 | I11: 10.05 | J11: Measured Cap | K11: =IF(G11="Fail","Fail",IF(ABS(I11-H11)/IF(H11=0,1,H11)<=0.1,"Pass","Fail")) -> Pass | L11: Tolerance | M11: Pass | N11: =IF(AND(G11="Pass",K11="Pass",M11="Pass"),"PASS","FAIL") -> PASS | O11: =IF(N11="PASS","Release to practicum","Quarantine — do not issue to students") -> Release to practicum
A12: 5 | B12: D-1N4007 | C12: Rectifier Diode | D12: LOT-A-805 | E12: 06-Apr-2026 | F12: 20 | G12: Pass | H12: 0.7 | I12: 0.69 | J12: Vf Measured | K12: =IF(G12="Fail","Fail",IF(ABS(I12-H12)/IF(H12=0,1,H12)<=0.1,"Pass","Fail")) -> Pass | L12: Continuity | M12: Pass | N12: =IF(AND(G12="Pass",K12="Pass",M12="Pass"),"PASS","FAIL") -> PASS | O12: =IF(N12="PASS","Release to practicum","Quarantine — do not issue to students") -> Release to practicum
A13: 6 | B13: D-1N4148 | C13: Signal Diode | D13: LOT-A-644 | E13: 06-Apr-2026 | F13: 23 | G13: Pass | H13: 0.6 | I13: 0.59 | J13: Vf Measured | K13: =IF(G13="Fail","Fail",IF(ABS(I13-H13)/IF(H13=0,1,H13)<=0.1,"Pass","Fail")) -> Pass | L13: Continuity | M13: Fail | N13: =IF(AND(G13="Pass",K13="Pass",M13="Pass"),"PASS","FAIL") -> FAIL | O13: =IF(N13="PASS","Release to practicum","Quarantine — do not issue to students") -> Quarantine — do not issue to students
A14: 7 | B14: Q-BC547 | C14: NPN Transistor | D14: LOT-A-743 | E14: 06-Apr-2026 | F14: 23 | G14: Pass | H14: 110 | I14: 100.08 | J14: hFE Measured | K14: =IF(G14="Fail","Fail",IF(ABS(I14-H14)/IF(H14=0,1,H14)<=0.1,"Pass","Fail")) -> Pass | L14: Vce_sat | M14: Pass | N14: =IF(AND(G14="Pass",K14="Pass",M14="Pass"),"PASS","FAIL") -> PASS | O14: =IF(N14="PASS","Release to practicum","Quarantine — do not issue to students") -> Release to practicum
A15: 8 | B15: Q-BC557 | C15: PNP Transistor | D15: LOT-A-499 | E15: 06-Apr-2026 | F15: 24 | G15: Pass | H15: 110 | I15: 117.75 | J15: hFE Measured | K15: =IF(G15="Fail","Fail",IF(ABS(I15-H15)/IF(H15=0,1,H15)<=0.1,"Pass","Fail")) -> Pass | L15: Vce_sat | M15: Pass | N15: =IF(AND(G15="Pass",K15="Pass",M15="Pass"),"PASS","FAIL") -> PASS | O15: =IF(N15="PASS","Release to practicum","Quarantine — do not issue to students") -> Release to practicum
A16: 9 | B16: U-LM741 | C16: Op-Amp IC | D16: LOT-A-424 | E16: 07-Apr-2026 | F16: 21 | G16: Pass | H16: 5 | I16: 5.49 | J16: VOS Measured | K16: =IF(G16="Fail","Fail",IF(ABS(I16-H16)/IF(H16=0,1,H16)<=0.1,"Pass","Fail")) -> Pass | L16: Pin Continuity | M16: Pass | N16: =IF(AND(G16="Pass",K16="Pass",M16="Pass"),"PASS","FAIL") -> PASS | O16: =IF(N16="PASS","Release to practicum","Quarantine — do not issue to students") -> Release to practicum
A17: 10 | B17: U-LM324 | C17: Quad Op-Amp IC | D17: LOT-A-141 | E17: 07-Apr-2026 | F17: 22 | G17: Pass | H17: 5 | I17: 5.31 | J17: VOS Measured | K17: =IF(G17="Fail","Fail",IF(ABS(I17-H17)/IF(H17=0,1,H17)<=0.1,"Pass","Fail")) -> Pass | L17: Pin Continuity | M17: Pass | N17: =IF(AND(G17="Pass",K17="Pass",M17="Pass"),"PASS","FAIL") -> PASS | O17: =IF(N17="PASS","Release to practicum","Quarantine — do not issue to students") -> Release to practicum
A18: 11 | B18: U-LM7805 | C18: Voltage Reg +5V | D18: LOT-A-964 | E18: 07-Apr-2026 | F18: 24 | G18: Pass | H18: 5 | I18: 5.33 | J18: Vout Measured | K18: =IF(G18="Fail","Fail",IF(ABS(I18-H18)/IF(H18=0,1,H18)<=0.1,"Pass","Fail")) -> Pass | L18: Load Reg Test | M18: Pass | N18: =IF(AND(G18="Pass",K18="Pass",M18="Pass"),"PASS","FAIL") -> PASS | O18: =IF(N18="PASS","Release to practicum","Quarantine — do not issue to students") -> Release to practicum
A19: 12 | B19: POT-10kΩ | C19: Potentiometer 10k | D19: LOT-A-728 | E19: 07-Apr-2026 | F19: 21 | G19: Pass | H19: 10 | I19: 10.84 | J19: Measured R | K19: =IF(G19="Fail","Fail",IF(ABS(I19-H19)/IF(H19=0,1,H19)<=0.1,"Pass","Fail")) -> Pass | L19: Sweep Test | M19: Pass | N19: =IF(AND(G19="Pass",K19="Pass",M19="Pass"),"PASS","FAIL") -> PASS | O19: =IF(N19="PASS","Release to practicum","Quarantine — do not issue to students") -> Release to practicum
A21: Inspection Session: Sesi B — Week 2 | Batch: LOT-B-2025
A22: 1 | B22: R-10kΩ-CFR | C22: Resistor 10kΩ | D22: LOT-B-341 | E22: 12-Apr-2026 | F22: 25 | G22: Pass | H22: 10 | I22: 9.68 | J22: Measured Value | K22: =IF(G22="Fail","Fail",IF(ABS(I22-H22)/IF(H22=0,1,H22)<=0.1,"Pass","Fail")) -> Pass | L22: Tolerance | M22: Pass | N22: =IF(AND(G22="Pass",K22="Pass",M22="Pass"),"PASS","FAIL") -> PASS | O22: =IF(N22="PASS","Release to practicum","Quarantine — do not issue to students") -> Release to practicum
A23: 2 | B23: R-1kΩ-CFR | C23: Resistor 1kΩ | D23: LOT-B-709 | E23: 12-Apr-2026 | F23: 23 | G23: Pass | H23: 1 | I23: 0.91 | J23: Measured Value | K23: =IF(G23="Fail","Fail",IF(ABS(I23-H23)/IF(H23=0,1,H23)<=0.1,"Pass","Fail")) -> Pass | L23: Tolerance | M23: Pass | N23: =IF(AND(G23="Pass",K23="Pass",M23="Pass"),"PASS","FAIL") -> PASS | O23: =IF(N23="PASS","Release to practicum","Quarantine — do not issue to students") -> Release to practicum
A24: 3 | B24: C-100µF-EC | C24: Capacitor 100µF | D24: LOT-B-443 | E24: 12-Apr-2026 | F24: 20 | G24: Pass | H24: 100 | I24: 111.98 | J24: Measured Cap | K24: =IF(G24="Fail","Fail",IF(ABS(I24-H24)/IF(H24=0,1,H24)<=0.1,"Pass","Fail")) -> Fail | L24: ESR Test | M24: Pass | N24: =IF(AND(G24="Pass",K24="Pass",M24="Pass"),"PASS","FAIL") -> FAIL | O24: =IF(N24="PASS","Release to practicum","Quarantine — do not issue to students") -> Quarantine — do not issue to students
A25: 4 | B25: C-10nF-MLC | C25: Capacitor 10nF | D25: LOT-B-800 | E25: 12-Apr-2026 | F25: 21 | G25: Pass | H25: 10 | I25: 10.87 | J25: Measured Cap | K25: =IF(G25="Fail","Fail",IF(ABS(I25-H25)/IF(H25=0,1,H25)<=0.1,"Pass","Fail")) -> Pass | L25: Tolerance | M25: Pass | N25: =IF(AND(G25="Pass",K25="Pass",M25="Pass"),"PASS","FAIL") -> PASS | O25: =IF(N25="PASS","Release to practicum","Quarantine — do not issue to students") -> Release to practicum
A26: 5 | B26: D-1N4007 | C26: Rectifier Diode | D26: LOT-B-694 | E26: 13-Apr-2026 | F26: 18 | G26: Pass | H26: 0.7 | I26: 0.63 | J26: Vf Measured | K26: =IF(G26="Fail","Fail",IF(ABS(I26-H26)/IF(H26=0,1,H26)<=0.1,"Pass","Fail")) -> Pass | L26: Continuity | M26: Pass | N26: =IF(AND(G26="Pass",K26="Pass",M26="Pass"),"PASS","FAIL") -> PASS | O26: =IF(N26="PASS","Release to practicum","Quarantine — do not issue to students") -> Release to practicum
A27: 6 | B27: D-1N4148 | C27: Signal Diode | D27: LOT-B-254 | E27: 13-Apr-2026 | F27: 21 | G27: Pass | H27: 0.6 | I27: 0.56 | J27: Vf Measured | K27: =IF(G27="Fail","Fail",IF(ABS(I27-H27)/IF(H27=0,1,H27)<=0.1,"Pass","Fail")) -> Pass | L27: Continuity | M27: Pass | N27: =IF(AND(G27="Pass",K27="Pass",M27="Pass"),"PASS","FAIL") -> PASS | O27: =IF(N27="PASS","Release to practicum","Quarantine — do not issue to students") -> Release to practicum
A28: 7 | B28: Q-BC547 | C28: NPN Transistor | D28: LOT-B-922 | E28: 13-Apr-2026 | F28: 25 | G28: Pass | H28: 110 | I28: 115.15 | J28: hFE Measured | K28: =IF(G28="Fail","Fail",IF(ABS(I28-H28)/IF(H28=0,1,H28)<=0.1,"Pass","Fail")) -> Pass | L28: Vce_sat | M28: Pass | N28: =IF(AND(G28="Pass",K28="Pass",M28="Pass"),"PASS","FAIL") -> PASS | O28: =IF(N28="PASS","Release to practicum","Quarantine — do not issue to students") -> Release to practicum
A29: 8 | B29: Q-BC557 | C29: PNP Transistor | D29: LOT-B-636 | E29: 13-Apr-2026 | F29: 19 | G29: Pass | H29: 110 | I29: 114.33 | J29: hFE Measured | K29: =IF(G29="Fail","Fail",IF(ABS(I29-H29)/IF(H29=0,1,H29)<=0.1,"Pass","Fail")) -> Pass | L29: Vce_sat | M29: Pass | N29: =IF(AND(G29="Pass",K29="Pass",M29="Pass"),"PASS","FAIL") -> PASS | O29: =IF(N29="PASS","Release to practicum","Quarantine — do not issue to students") -> Release to practicum
A30: 9 | B30: U-LM741 | C30: Op-Amp IC | D30: LOT-B-408 | E30: 14-Apr-2026 | F30: 22 | G30: Pass | H30: 5 | I30: 4.56 | J30: VOS Measured | K30: =IF(G30="Fail","Fail",IF(ABS(I30-H30)/IF(H30=0,1,H30)<=0.1,"Pass","Fail")) -> Pass | L30: Pin Continuity | M30: Pass | N30: =IF(AND(G30="Pass",K30="Pass",M30="Pass"),"PASS","FAIL") -> PASS | O30: =IF(N30="PASS","Release to practicum","Quarantine — do not issue to students") -> Release to practicum
A31: 10 | B31: U-LM324 | C31: Quad Op-Amp IC | D31: LOT-B-639 | E31: 14-Apr-2026 | F31: 24 | G31: Pass | H31: 5 | I31: 4.66 | J31: VOS Measured | K31: =IF(G31="Fail","Fail",IF(ABS(I31-H31)/IF(H31=0,1,H31)<=0.1,"Pass","Fail")) -> Pass | L31: Pin Continuity | M31: Pass | N31: =IF(AND(G31="Pass",K31="Pass",M31="Pass"),"PASS","FAIL") -> PASS | O31: =IF(N31="PASS","Release to practicum","Quarantine — do not issue to students") -> Release to practicum
A32: 11 | B32: U-LM7805 | C32: Voltage Reg +5V | D32: LOT-B-280 | E32: 14-Apr-2026 | F32: 18 | G32: Pass | H32: 5 | I32: 4.67 | J32: Vout Measured | K32: =IF(G32="Fail","Fail",IF(ABS(I32-H32)/IF(H32=0,1,H32)<=0.1,"Pass","Fail")) -> Pass | L32: Load Reg Test | M32: Pass | N32: =IF(AND(G32="Pass",K32="Pass",M32="Pass"),"PASS","FAIL") -> PASS | O32: =IF(N32="PASS","Release to practicum","Quarantine — do not issue to students") -> Release to practicum
A33: 12 | B33: POT-10kΩ | C33: Potentiometer 10k | D33: LOT-B-692 | E33: 14-Apr-2026 | F33: 19 | G33: Pass | H33: 10 | I33: 10.43 | J33: Measured R | K33: =IF(G33="Fail","Fail",IF(ABS(I33-H33)/IF(H33=0,1,H33)<=0.1,"Pass","Fail")) -> Pass | L33: Sweep Test | M33: Pass | N33: =IF(AND(G33="Pass",K33="Pass",M33="Pass"),"PASS","FAIL") -> PASS | O33: =IF(N33="PASS","Release to practicum","Quarantine — do not issue to students") -> Release to practicum
A35: Inspection Session: Sesi C — Week 3 | Batch: LOT-C-2026
A36: 1 | B36: R-10kΩ-CFR | C36: Resistor 10kΩ | D36: LOT-C-221 | E36: 19-Apr-2026 | F36: 21 | G36: Pass | H36: 10 | I36: 10.04 | J36: Measured Value | K36: =IF(G36="Fail","Fail",IF(ABS(I36-H36)/IF(H36=0,1,H36)<=0.1,"Pass","Fail")) -> Pass | L36: Tolerance | M36: Pass | N36: =IF(AND(G36="Pass",K36="Pass",M36="Pass"),"PASS","FAIL") -> PASS | O36: =IF(N36="PASS","Release to practicum","Quarantine — do not issue to students") -> Release to practicum
A37: 2 | B37: R-1kΩ-CFR | C37: Resistor 1kΩ | D37: LOT-C-750 | E37: 19-Apr-2026 | F37: 21 | G37: Pass | H37: 1 | I37: 0.9 | J37: Measured Value | K37: =IF(G37="Fail","Fail",IF(ABS(I37-H37)/IF(H37=0,1,H37)<=0.1,"Pass","Fail")) -> Pass | L37: Tolerance | M37: Pass | N37: =IF(AND(G37="Pass",K37="Pass",M37="Pass"),"PASS","FAIL") -> PASS | O37: =IF(N37="PASS","Release to practicum","Quarantine — do not issue to students") -> Release to practicum
A38: 3 | B38: C-100µF-EC | C38: Capacitor 100µF | D38: LOT-C-599 | E38: 19-Apr-2026 | F38: 20 | G38: Pass | H38: 100 | I38: 105.56 | J38: Measured Cap | K38: =IF(G38="Fail","Fail",IF(ABS(I38-H38)/IF(H38=0,1,H38)<=0.1,"Pass","Fail")) -> Pass | L38: ESR Test | M38: Pass | N38: =IF(AND(G38="Pass",K38="Pass",M38="Pass"),"PASS","FAIL") -> PASS | O38: =IF(N38="PASS","Release to practicum","Quarantine — do not issue to students") -> Release to practicum
A39: 4 | B39: C-10nF-MLC | C39: Capacitor 10nF | D39: LOT-C-732 | E39: 19-Apr-2026 | F39: 18 | G39: Pass | H39: 10 | I39: 11.06 | J39: Measured Cap | K39: =IF(G39="Fail","Fail",IF(ABS(I39-H39)/IF(H39=0,1,H39)<=0.1,"Pass","Fail")) -> Fail | L39: Tolerance | M39: Pass | N39: =IF(AND(G39="Pass",K39="Pass",M39="Pass"),"PASS","FAIL") -> FAIL | O39: =IF(N39="PASS","Release to practicum","Quarantine — do not issue to students") -> Quarantine — do not issue to students
A40: 5 | B40: D-1N4007 | C40: Rectifier Diode | D40: LOT-C-709 | E40: 20-Apr-2026 | F40: 18 | G40: Pass | H40: 0.7 | I40: 0.65 | J40: Vf Measured | K40: =IF(G40="Fail","Fail",IF(ABS(I40-H40)/IF(H40=0,1,H40)<=0.1,"Pass","Fail")) -> Pass | L40: Continuity | M40: Pass | N40: =IF(AND(G40="Pass",K40="Pass",M40="Pass"),"PASS","FAIL") -> PASS | O40: =IF(N40="PASS","Release to practicum","Quarantine — do not issue to students") -> Release to practicum
A41: 6 | B41: D-1N4148 | C41: Signal Diode | D41: LOT-C-225 | E41: 20-Apr-2026 | F41: 21 | G41: Pass | H41: 0.6 | I41: 0.55 | J41: Vf Measured | K41: =IF(G41="Fail","Fail",IF(ABS(I41-H41)/IF(H41=0,1,H41)<=0.1,"Pass","Fail")) -> Pass | L41: Continuity | M41: Pass | N41: =IF(AND(G41="Pass",K41="Pass",M41="Pass"),"PASS","FAIL") -> PASS | O41: =IF(N41="PASS","Release to practicum","Quarantine — do not issue to students") -> Release to practicum
A42: 7 | B42: Q-BC547 | C42: NPN Transistor | D42: LOT-C-693 | E42: 20-Apr-2026 | F42: 23 | G42: Pass | H42: 110 | I42: 101.82 | J42: hFE Measured | K42: =IF(G42="Fail","Fail",IF(ABS(I42-H42)/IF(H42=0,1,H42)<=0.1,"Pass","Fail")) -> Pass | L42: Vce_sat | M42: Pass | N42: =IF(AND(G42="Pass",K42="Pass",M42="Pass"),"PASS","FAIL") -> PASS | O42: =IF(N42="PASS","Release to practicum","Quarantine — do not issue to students") -> Release to practicum
A43: 8 | B43: Q-BC557 | C43: PNP Transistor | D43: LOT-C-379 | E43: 20-Apr-2026 | F43: 21 | G43: Pass | H43: 110 | I43: 113.55 | J43: hFE Measured | K43: =IF(G43="Fail","Fail",IF(ABS(I43-H43)/IF(H43=0,1,H43)<=0.1,"Pass","Fail")) -> Pass | L43: Vce_sat | M43: Pass | N43: =IF(AND(G43="Pass",K43="Pass",M43="Pass"),"PASS","FAIL") -> PASS | O43: =IF(N43="PASS","Release to practicum","Quarantine — do not issue to students") -> Release to practicum
...

Sheet Elek_Digital
A1: PRAKTIKUM ELEKTRONIKA DIGITAL — COMPONENT QC INSPECTION LOG
A2: Lab Sensor & Sistem Telekontrol (SSTK) | Dept. Teknik Nuklir & Teknik Fisika, UGM | ~20 Mahasiswa/Sesi
A3: Test Equipment: Multimeter (Sanwa CD771), Digital Logic Probe, DC Power Supply (HY3005F), Function Generator
A5: No. | B5: Part Number | C5: Component Description | D5: Batch / Lot No. | E5: Inspection Date | F5: Qty | G5: Visual Inspection | H5: Spec / Rated Value | I5: Measured Value | J5: Functional Test 1 | K5: Test 1 Result | L5: Functional Test 2 | M5: Test 2 Result | N5: Overall Result | O5: Remarks / Disposition
A6: ⚠ Columns shaded yellow = manual input per inspection session | Columns shaded gray = auto-calculated by formula | Overall Result = auto (PASS only if ALL tests pass)
A7: Inspection Session: Sesi A — Week 1 | Batch: LOT-A-2024
A8: 1 | B8: IC-74LS00 | C8: NAND Gate (Quad) | D8: LOT-A-949 | E8: 05-Apr-2026 | F8: 22 | G8: Pass | H8: 5 | I8: 4.7 | J8: VCC Test | K8: =IF(G8="Fail","Fail",IF(ABS(I8-H8)/IF(H8=0,1,H8)<=0.1,"Pass","Fail")) -> Pass | L8: Logic Function Test | M8: Pass | N8: =IF(AND(G8="Pass",K8="Pass",M8="Pass"),"PASS","FAIL") -> PASS | O8: =IF(N8="PASS","Release to practicum","Quarantine — do not issue to students") -> Release to practicum
A9: 2 | B9: IC-74LS08 | C9: AND Gate (Quad) | D9: LOT-A-934 | E9: 05-Apr-2026 | F9: 24 | G9: Pass | H9: 5 | I9: 4.83 | J9: VCC Test | K9: =IF(G9="Fail","Fail",IF(ABS(I9-H9)/IF(H9=0,1,H9)<=0.1,"Pass","Fail")) -> Pass | L9: Logic Function Test | M9: Pass | N9: =IF(AND(G9="Pass",K9="Pass",M9="Pass"),"PASS","FAIL") -> PASS | O9: =IF(N9="PASS","Release to practicum","Quarantine — do not issue to students") -> Release to practicum
A10: 3 | B10: IC-74LS86 | C10: XOR Gate (Quad) | D10: LOT-A-507 | E10: 05-Apr-2026 | F10: 21 | G10: Pass | H10: 5 | I10: 4.78 | J10: VCC Test | K10: =IF(G10="Fail","Fail",IF(ABS(I10-H10)/IF(H10=0,1,H10)<=0.1,"Pass","Fail")) -> Pass | L10: Logic Function Test | M10: Pass | N10: =IF(AND(G10="Pass",K10="Pass",M10="Pass"),"PASS","FAIL") -> PASS | O10: =IF(N10="PASS","Release to practicum","Quarantine — do not issue to students") -> Release to practicum
A11: 4 | B11: IC-74LS74 | C11: D Flip-Flop | D11: LOT-A-942 | E11: 05-Apr-2026 | F11: 25 | G11: Pass | H11: 5 | I11: 4.83 | J11: VCC Test | K11: =IF(G11="Fail","Fail",IF(ABS(I11-H11)/IF(H11=0,1,H11)<=0.1,"Pass","Fail")) -> Pass | L11: Toggle Test | M11: Pass | N11: =IF(AND(G11="Pass",K11="Pass",M11="Pass"),"PASS","FAIL") -> PASS | O11: =IF(N11="PASS","Release to practicum","Quarantine — do not issue to students") -> Release to practicum
A12: 5 | B12: IC-74LS163 | C12: 4-bit Counter | D12: LOT-A-686 | E12: 06-Apr-2026 | F12: 21 | G12: Pass | H12: 5 | I12: 5.55 | J12: VCC Test | K12: =IF(G12="Fail","Fail",IF(ABS(I12-H12)/IF(H12=0,1,H12)<=0.1,"Pass","Fail")) -> Fail | L12: Count Sequence Test | M12: Pass | N12: =IF(AND(G12="Pass",K12="Pass",M12="Pass"),"PASS","FAIL") -> FAIL | O12: =IF(N12="PASS","Release to practicum","Quarantine — do not issue to students") -> Quarantine — do not issue to students
A13: 6 | B13: IC-555 | C13: Timer IC | D13: LOT-A-579 | E13: 06-Apr-2026 | F13: 21 | G13: Pass | H13: 15 | I13: 13.39 | J13: VCC Test | K13: =IF(G13="Fail","Fail",IF(ABS(I13-H13)/IF(H13=0,1,H13)<=0.1,"Pass","Fail")) -> Fail | L13: Oscillation Test | M13: Pass | N13: =IF(AND(G13="Pass",K13="Pass",M13="Pass"),"PASS","FAIL") -> FAIL | O13: =IF(N13="PASS","Release to practicum","Quarantine — do not issue to students") -> Quarantine — do not issue to students
A14: 7 | B14: RLY-G2R-DC5 | C14: Relay SPDT 5VDC | D14: LOT-A-369 | E14: 06-Apr-2026 | F14: 20 | G14: Pass | H14: 70 | I14: 63.86 | J14: Coil R Meas | K14: =IF(G14="Fail","Fail",IF(ABS(I14-H14)/IF(H14=0,1,H14)<=0.1,"Pass","Fail")) -> Pass | L14: Switching Test | M14: Pass | N14: =IF(AND(G14="Pass",K14="Pass",M14="Pass"),"PASS","FAIL") -> PASS | O14: =IF(N14="PASS","Release to practicum","Quarantine — do not issue to students") -> Release to practicum
A15: 8 | B15: RLY-SRD-12V | C15: Relay SPDT 12VDC | D15: LOT-A-882 | E15: 06-Apr-2026 | F15: 22 | G15: Pass | H15: 400 | I15: 373.14 | J15: Coil R Meas | K15: =IF(G15="Fail","Fail",IF(ABS(I15-H15)/IF(H15=0,1,H15)<=0.1,"Pass","Fail")) -> Pass | L15: Switching Test | M15: Pass | N15: =IF(AND(G15="Pass",K15="Pass",M15="Pass"),"PASS","FAIL") -> PASS | O15: =IF(N15="PASS","Release to practicum","Quarantine — do not issue to students") -> Release to practicum
A16: 9 | B16: SW-TACT-6mm | C16: Tactile Switch | D16: LOT-A-353 | E16: 07-Apr-2026 | F16: 20 | G16: Pass | H16: 0.5 | I16: 0.49 | J16: Contact R | K16: =IF(G16="Fail","Fail",IF(ABS(I16-H16)/IF(H16=0,1,H16)<=0.1,"Pass","Fail")) -> Pass | L16: Continuity Test | M16: Pass | N16: =IF(AND(G16="Pass",K16="Pass",M16="Pass"),"PASS","FAIL") -> PASS | O16: =IF(N16="PASS","Release to practicum","Quarantine — do not issue to students") -> Release to practicum
A17: 10 | B17: SW-SLIDE | C17: Slide Switch SPDT | D17: LOT-A-591 | E17: 07-Apr-2026 | F17: 24 | G17: Pass | H17: 0.5 | I17: 0.56 | J17: Contact R | K17: =IF(G17="Fail","Fail",IF(ABS(I17-H17)/IF(H17=0,1,H17)<=0.1,"Pass","Fail")) -> Fail | L17: Continuity Test | M17: Pass | N17: =IF(AND(G17="Pass",K17="Pass",M17="Pass"),"PASS","FAIL") -> FAIL | O17: =IF(N17="PASS","Release to practicum","Quarantine — do not issue to students") -> Quarantine — do not issue to students
A18: 11 | B18: LED-RED-5mm | C18: LED Red 5mm | D18: LOT-A-811 | E18: 07-Apr-2026 | F18: 24 | G18: Fail | H18: 2 | I18: 2.11 | J18: Vf Meas | K18: =IF(G18="Fail","Fail",IF(ABS(I18-H18)/IF(H18=0,1,H18)<=0.1,"Pass","Fail")) -> Fail | L18: Brightness Check | M18: Pass | N18: =IF(AND(G18="Pass",K18="Pass",M18="Pass"),"PASS","FAIL") -> FAIL | O18: =IF(N18="PASS","Release to practicum","Quarantine — do not issue to students") -> Quarantine — do not issue to students
A19: 12 | B19: LED-GRN-5mm | C19: LED Green 5mm | D19: LOT-A-726 | E19: 07-Apr-2026 | F19: 19 | G19: Pass | H19: 2.1 | I19: 2.35 | J19: Vf Meas | K19: =IF(G19="Fail","Fail",IF(ABS(I19-H19)/IF(H19=0,1,H19)<=0.1,"Pass","Fail")) -> Fail | L19: Brightness Check | M19: Pass | N19: =IF(AND(G19="Pass",K19="Pass",M19="Pass"),"PASS","FAIL") -> FAIL | O19: =IF(N19="PASS","Release to practicum","Quarantine — do not issue to students") -> Quarantine — do not issue to students
A21: Inspection Session: Sesi B — Week 2 | Batch: LOT-B-2025
A22: 1 | B22: IC-74LS00 | C22: NAND Gate (Quad) | D22: LOT-B-876 | E22: 12-Apr-2026 | F22: 22 | G22: Pass | H22: 5 | I22: 4.44 | J22: VCC Test | K22: =IF(G22="Fail","Fail",IF(ABS(I22-H22)/IF(H22=0,1,H22)<=0.1,"Pass","Fail")) -> Fail | L22: Logic Function Test | M22: Pass | N22: =IF(AND(G22="Pass",K22="Pass",M22="Pass"),"PASS","FAIL") -> FAIL | O22: =IF(N22="PASS","Release to practicum","Quarantine — do not issue to students") -> Quarantine — do not issue to students
A23: 2 | B23: IC-74LS08 | C23: AND Gate (Quad) | D23: LOT-B-786 | E23: 12-Apr-2026 | F23: 24 | G23: Pass | H23: 5 | I23: 4.63 | J23: VCC Test | K23: =IF(G23="Fail","Fail",IF(ABS(I23-H23)/IF(H23=0,1,H23)<=0.1,"Pass","Fail")) -> Pass | L23: Logic Function Test | M23: Pass | N23: =IF(AND(G23="Pass",K23="Pass",M23="Pass"),"PASS","FAIL") -> PASS | O23: =IF(N23="PASS","Release to practicum","Quarantine — do not issue to students") -> Release to practicum
A24: 3 | B24: IC-74LS86 | C24: XOR Gate (Quad) | D24: LOT-B-271 | E24: 12-Apr-2026 | F24: 25 | G24: Pass | H24: 5 | I24: 4.97 | J24: VCC Test | K24: =IF(G24="Fail","Fail",IF(ABS(I24-H24)/IF(H24=0,1,H24)<=0.1,"Pass","Fail")) -> Pass | L24: Logic Function Test | M24: Pass | N24: =IF(AND(G24="Pass",K24="Pass",M24="Pass"),"PASS","FAIL") -> PASS | O24: =IF(N24="PASS","Release to practicum","Quarantine — do not issue to students") -> Release to practicum
A25: 4 | B25: IC-74LS74 | C25: D Flip-Flop | D25: LOT-B-227 | E25: 12-Apr-2026 | F25: 19 | G25: Pass | H25: 5 | I25: 4.72 | J25: VCC Test | K25: =IF(G25="Fail","Fail",IF(ABS(I25-H25)/IF(H25=0,1,H25)<=0.1,"Pass","Fail")) -> Pass | L25: Toggle Test | M25: Pass | N25: =IF(AND(G25="Pass",K25="Pass",M25="Pass"),"PASS","FAIL") -> PASS | O25: =IF(N25="PASS","Release to practicum","Quarantine — do not issue to students") -> Release to practicum
A26: 5 | B26: IC-74LS163 | C26: 4-bit Counter | D26: LOT-B-328 | E26: 13-Apr-2026 | F26: 20 | G26: Pass | H26: 5 | I26: 4.68 | J26: VCC Test | K26: =IF(G26="Fail","Fail",IF(ABS(I26-H26)/IF(H26=0,1,H26)<=0.1,"Pass","Fail")) -> Pass | L26: Count Sequence Test | M26: Pass | N26: =IF(AND(G26="Pass",K26="Pass",M26="Pass"),"PASS","FAIL") -> PASS | O26: =IF(N26="PASS","Release to practicum","Quarantine — do not issue to students") -> Release to practicum
A27: 6 | B27: IC-555 | C27: Timer IC | D27: LOT-B-936 | E27: 13-Apr-2026 | F27: 20 | G27: Pass | H27: 15 | I27: 16.11 | J27: VCC Test | K27: =IF(G27="Fail","Fail",IF(ABS(I27-H27)/IF(H27=0,1,H27)<=0.1,"Pass","Fail")) -> Pass | L27: Oscillation Test | M27: Pass | N27: =IF(AND(G27="Pass",K27="Pass",M27="Pass"),"PASS","FAIL") -> PASS | O27: =IF(N27="PASS","Release to practicum","Quarantine — do not issue to students") -> Release to practicum
A28: 7 | B28: RLY-G2R-DC5 | C28: Relay SPDT 5VDC | D28: LOT-B-446 | E28: 13-Apr-2026 | F28: 21 | G28: Pass | H28: 70 | I28: 72.18 | J28: Coil R Meas | K28: =IF(G28="Fail","Fail",IF(ABS(I28-H28)/IF(H28=0,1,H28)<=0.1,"Pass","Fail")) -> Pass | L28: Switching Test | M28: Pass | N28: =IF(AND(G28="Pass",K28="Pass",M28="Pass"),"PASS","FAIL") -> PASS | O28: =IF(N28="PASS","Release to practicum","Quarantine — do not issue to students") -> Release to practicum
A29: 8 | B29: RLY-SRD-12V | C29: Relay SPDT 12VDC | D29: LOT-B-120 | E29: 13-Apr-2026 | F29: 20 | G29: Pass | H29: 400 | I29: 388.67 | J29: Coil R Meas | K29: =IF(G29="Fail","Fail",IF(ABS(I29-H29)/IF(H29=0,1,H29)<=0.1,"Pass","Fail")) -> Pass | L29: Switching Test | M29: Pass | N29: =IF(AND(G29="Pass",K29="Pass",M29="Pass"),"PASS","FAIL") -> PASS | O29: =IF(N29="PASS","Release to practicum","Quarantine — do not issue to students") -> Release to practicum
A30: 9 | B30: SW-TACT-6mm | C30: Tactile Switch | D30: LOT-B-618 | E30: 14-Apr-2026 | F30: 20 | G30: Pass | H30: 0.5 | I30: 0.47 | J30: Contact R | K30: =IF(G30="Fail","Fail",IF(ABS(I30-H30)/IF(H30=0,1,H30)<=0.1,"Pass","Fail")) -> Pass | L30: Continuity Test | M30: Pass | N30: =IF(AND(G30="Pass",K30="Pass",M30="Pass"),"PASS","FAIL") -> PASS | O30: =IF(N30="PASS","Release to practicum","Quarantine — do not issue to students") -> Release to practicum
A31: 10 | B31: SW-SLIDE | C31: Slide Switch SPDT | D31: LOT-B-819 | E31: 14-Apr-2026 | F31: 20 | G31: Pass | H31: 0.5 | I31: 0.51 | J31: Contact R | K31: =IF(G31="Fail","Fail",IF(ABS(I31-H31)/IF(H31=0,1,H31)<=0.1,"Pass","Fail")) -> Pass | L31: Continuity Test | M31: Pass | N31: =IF(AND(G31="Pass",K31="Pass",M31="Pass"),"PASS","FAIL") -> PASS | O31: =IF(N31="PASS","Release to practicum","Quarantine — do not issue to students") -> Release to practicum
A32: 11 | B32: LED-RED-5mm | C32: LED Red 5mm | D32: LOT-B-791 | E32: 14-Apr-2026 | F32: 19 | G32: Pass | H32: 2 | I32: 1.88 | J32: Vf Meas | K32: =IF(G32="Fail","Fail",IF(ABS(I32-H32)/IF(H32=0,1,H32)<=0.1,"Pass","Fail")) -> Pass | L32: Brightness Check | M32: Pass | N32: =IF(AND(G32="Pass",K32="Pass",M32="Pass"),"PASS","FAIL") -> PASS | O32: =IF(N32="PASS","Release to practicum","Quarantine — do not issue to students") -> Release to practicum
A33: 12 | B33: LED-GRN-5mm | C33: LED Green 5mm | D33: LOT-B-533 | E33: 14-Apr-2026 | F33: 23 | G33: Pass | H33: 2.1 | I33: 1.86 | J33: Vf Meas | K33: =IF(G33="Fail","Fail",IF(ABS(I33-H33)/IF(H33=0,1,H33)<=0.1,"Pass","Fail")) -> Fail | L33: Brightness Check | M33: Pass | N33: =IF(AND(G33="Pass",K33="Pass",M33="Pass"),"PASS","FAIL") -> FAIL | O33: =IF(N33="PASS","Release to practicum","Quarantine — do not issue to students") -> Quarantine — do not issue to students
A35: Inspection Session: Sesi C — Week 3 | Batch: LOT-C-2026
A36: 1 | B36: IC-74LS00 | C36: NAND Gate (Quad) | D36: LOT-C-572 | E36: 19-Apr-2026 | F36: 25 | G36: Pass | H36: 5 | I36: 4.98 | J36: VCC Test | K36: =IF(G36="Fail","Fail",IF(ABS(I36-H36)/IF(H36=0,1,H36)<=0.1,"Pass","Fail")) -> Pass | L36: Logic Function Test | M36: Pass | N36: =IF(AND(G36="Pass",K36="Pass",M36="Pass"),"PASS","FAIL") -> PASS | O36: =IF(N36="PASS","Release to practicum","Quarantine — do not issue to students") -> Release to practicum
A37: 2 | B37: IC-74LS08 | C37: AND Gate (Quad) | D37: LOT-C-665 | E37: 19-Apr-2026 | F37: 24 | G37: Pass | H37: 5 | I37: 5.22 | J37: VCC Test | K37: =IF(G37="Fail","Fail",IF(ABS(I37-H37)/IF(H37=0,1,H37)<=0.1,"Pass","Fail")) -> Pass | L37: Logic Function Test | M37: Pass | N37: =IF(AND(G37="Pass",K37="Pass",M37="Pass"),"PASS","FAIL") -> PASS | O37: =IF(N37="PASS","Release to practicum","Quarantine — do not issue to students") -> Release to practicum
A38: 3 | B38: IC-74LS86 | C38: XOR Gate (Quad) | D38: LOT-C-766 | E38: 19-Apr-2026 | F38: 23 | G38: Pass | H38: 5 | I38: 5.17 | J38: VCC Test | K38: =IF(G38="Fail","Fail",IF(ABS(I38-H38)/IF(H38=0,1,H38)<=0.1,"Pass","Fail")) -> Pass | L38: Logic Function Test | M38: Pass | N38: =IF(AND(G38="Pass",K38="Pass",M38="Pass"),"PASS","FAIL") -> PASS | O38: =IF(N38="PASS","Release to practicum","Quarantine — do not issue to students") -> Release to practicum
A39: 4 | B39: IC-74LS74 | C39: D Flip-Flop | D39: LOT-C-261 | E39: 19-Apr-2026 | F39: 22 | G39: Fail | H39: 5 | I39: 5.28 | J39: VCC Test | K39: =IF(G39="Fail","Fail",IF(ABS(I39-H39)/IF(H39=0,1,H39)<=0.1,"Pass","Fail")) -> Fail | L39: Toggle Test | M39: Pass | N39: =IF(AND(G39="Pass",K39="Pass",M39="Pass"),"PASS","FAIL") -> FAIL | O39: =IF(N39="PASS","Release to practicum","Quarantine — do not issue to students") -> Quarantine — do not issue to students
A40: 5 | B40: IC-74LS163 | C40: 4-bit Counter | D40: LOT-C-301 | E40: 20-Apr-2026 | F40: 20 | G40: Pass | H40: 5 | I40: 4.96 | J40: VCC Test | K40: =IF(G40="Fail","Fail",IF(ABS(I40-H40)/IF(H40=0,1,H40)<=0.1,"Pass","Fail")) -> Pass | L40: Count Sequence Test | M40: Pass | N40: =IF(AND(G40="Pass",K40="Pass",M40="Pass"),"PASS","FAIL") -> PASS | O40: =IF(N40="PASS","Release to practicum","Quarantine — do not issue to students") -> Release to practicum
A41: 6 | B41: IC-555 | C41: Timer IC | D41: LOT-C-852 | E41: 20-Apr-2026 | F41: 19 | G41: Pass | H41: 15 | I41: 13.38 | J41: VCC Test | K41: =IF(G41="Fail","Fail",IF(ABS(I41-H41)/IF(H41=0,1,H41)<=0.1,"Pass","Fail")) -> Fail | L41: Oscillation Test | M41: Pass | N41: =IF(AND(G41="Pass",K41="Pass",M41="Pass"),"PASS","FAIL") -> FAIL | O41: =IF(N41="PASS","Release to practicum","Quarantine — do not issue to students") -> Quarantine — do not issue to students
A42: 7 | B42: RLY-G2R-DC5 | C42: Relay SPDT 5VDC | D42: LOT-C-825 | E42: 20-Apr-2026 | F42: 21 | G42: Pass | H42: 70 | I42: 72.87 | J42: Coil R Meas | K42: =IF(G42="Fail","Fail",IF(ABS(I42-H42)/IF(H42=0,1,H42)<=0.1,"Pass","Fail")) -> Pass | L42: Switching Test | M42: Pass | N42: =IF(AND(G42="Pass",K42="Pass",M42="Pass"),"PASS","FAIL") -> PASS | O42: =IF(N42="PASS","Release to practicum","Quarantine — do not issue to students") -> Release to practicum
A43: 8 | B43: RLY-SRD-12V | C43: Relay SPDT 12VDC | D43: LOT-C-639 | E43: 20-Apr-2026 | F43: 23 | G43: Pass | H43: 400 | I43: 423.94 | J43: Coil R Meas | K43: =IF(G43="Fail","Fail",IF(ABS(I43-H43)/IF(H43=0,1,H43)<=0.1,"Pass","Fail")) -> Pass | L43: Switching Test | M43: Pass | N43: =IF(AND(G43="Pass",K43="Pass",M43="Pass"),"PASS","FAIL") -> PASS | O43: =IF(N43="PASS","Release to practicum","Quarantine — do not issue to students") -> Release to practicum
...

Sheet Sistem_Instr
A1: PRAKTIKUM SISTEM INSTRUMENTASI — COMPONENT QC INSPECTION LOG
A2: Lab Sensor & Sistem Telekontrol (SSTK) | Dept. Teknik Nuklir & Teknik Fisika, UGM | ~20 Mahasiswa/Sesi
A3: Test Equipment: Multimeter (Sanwa CD771), DC Power Supply, Oscilloscope (GDS-1022), Arduino Uno (test harness), Serial Monitor
A5: No. | B5: Part Number | C5: Component Description | D5: Batch / Lot No. | E5: Inspection Date | F5: Qty | G5: Visual Inspection | H5: Spec / Rated Value | I5: Measured Value | J5: Functional Test 1 | K5: Test 1 Result | L5: Functional Test 2 | M5: Test 2 Result | N5: Overall Result | O5: Remarks / Disposition
A6: ⚠ Columns shaded yellow = manual input per inspection session | Columns shaded gray = auto-calculated by formula | Overall Result = auto (PASS only if ALL tests pass)
A7: Inspection Session: Sesi A — Week 1 | Batch: LOT-A-2024
A8: 1 | B8: SEN-LM35 | C8: Temp Sensor LM35 | D8: LOT-A-980 | E8: 05-Apr-2026 | F8: 22 | G8: Pass | H8: 10 | I8: 10.7 | J8: Output @25°C | K8: =IF(G8="Fail","Fail",IF(ABS(I8-H8)/IF(H8=0,1,H8)<=0.1,"Pass","Fail")) -> Pass | L8: Linearity Test | M8: Pass | N8: =IF(AND(G8="Pass",K8="Pass",M8="Pass"),"PASS","FAIL") -> PASS | O8: =IF(N8="PASS","Release to practicum","Quarantine — do not issue to students") -> Release to practicum
A9: 2 | B9: SEN-DS18B20 | C9: 1-Wire Temp Sensor | D9: LOT-A-758 | E9: 05-Apr-2026 | F9: 22 | G9: Pass | H9: 0.5 | I9: 0.54 | J9: Measured Err | K9: =IF(G9="Fail","Fail",IF(ABS(I9-H9)/IF(H9=0,1,H9)<=0.1,"Pass","Fail")) -> Pass | L9: Communication Test | M9: Pass | N9: =IF(AND(G9="Pass",K9="Pass",M9="Pass"),"PASS","FAIL") -> PASS | O9: =IF(N9="PASS","Release to practicum","Quarantine — do not issue to students") -> Release to practicum
A10: 3 | B10: SEN-BMP180 | C10: Pressure Sensor | D10: LOT-A-214 | E10: 05-Apr-2026 | F10: 24 | G10: Fail | H10: 1 | I10: 1.09 | J10: Measured Err | K10: =IF(G10="Fail","Fail",IF(ABS(I10-H10)/IF(H10=0,1,H10)<=0.1,"Pass","Fail")) -> Fail | L10: I2C Comm Test | M10: Pass | N10: =IF(AND(G10="Pass",K10="Pass",M10="Pass"),"PASS","FAIL") -> FAIL | O10: =IF(N10="PASS","Release to practicum","Quarantine — do not issue to students") -> Quarantine — do not issue to students
A11: 4 | B11: SEN-LDR | C11: LDR Photo Sensor | D11: LOT-A-267 | E11: 05-Apr-2026 | F11: 22 | G11: Pass | H11: 10 | I11: 9.25 | J11: Dark R Meas | K11: =IF(G11="Fail","Fail",IF(ABS(I11-H11)/IF(H11=0,1,H11)<=0.1,"Pass","Fail")) -> Pass | L11: Light Response Test | M11: Pass | N11: =IF(AND(G11="Pass",K11="Pass",M11="Pass"),"PASS","FAIL") -> PASS | O11: =IF(N11="PASS","Release to practicum","Quarantine — do not issue to students") -> Release to practicum
A12: 5 | B12: SEN-PIR-HC | C12: PIR Motion Sensor | D12: LOT-A-161 | E12: 06-Apr-2026 | F12: 22 | G12: Pass | H12: 5 | I12: 4.6 | J12: Trigger Test | K12: =IF(G12="Fail","Fail",IF(ABS(I12-H12)/IF(H12=0,1,H12)<=0.1,"Pass","Fail")) -> Pass | L12: Detection Range | M12: Pass | N12: =IF(AND(G12="Pass",K12="Pass",M12="Pass"),"PASS","FAIL") -> PASS | O12: =IF(N12="PASS","Release to practicum","Quarantine — do not issue to students") -> Release to practicum
A13: 6 | B13: SEN-US-HC04 | C13: Ultrasonic HC-SR04 | D13: LOT-A-898 | E13: 06-Apr-2026 | F13: 22 | G13: Pass | H13: 400 | I13: 444.68 | J13: Accuracy | K13: =IF(G13="Fail","Fail",IF(ABS(I13-H13)/IF(H13=0,1,H13)<=0.1,"Pass","Fail")) -> Fail | L13: Echo Response Test | M13: Pass | N13: =IF(AND(G13="Pass",K13="Pass",M13="Pass"),"PASS","FAIL") -> FAIL | O13: =IF(N13="PASS","Release to practicum","Quarantine — do not issue to students") -> Quarantine — do not issue to students
A14: 7 | B14: MOD-ESP32 | C14: ESP32 MCU Module | D14: LOT-A-937 | E14: 06-Apr-2026 | F14: 20 | G14: Pass | H14: 3.3 | I14: 2.97 | J14: Boot Test | K14: =IF(G14="Fail","Fail",IF(ABS(I14-H14)/IF(H14=0,1,H14)<=0.1,"Pass","Fail")) -> Pass | L14: GPIO Continuity | M14: Pass | N14: =IF(AND(G14="Pass",K14="Pass",M14="Pass"),"PASS","FAIL") -> PASS | O14: =IF(N14="PASS","Release to practicum","Quarantine — do not issue to students") -> Release to practicum
A15: 8 | B15: MOD-ADS1115 | C15: ADC Module 16-bit | D15: LOT-A-210 | E15: 06-Apr-2026 | F15: 24 | G15: Pass | H15: 3.3 | I15: 3.53 | J15: I2C Comm Test | K15: =IF(G15="Fail","Fail",IF(ABS(I15-H15)/IF(H15=0,1,H15)<=0.1,"Pass","Fail")) -> Pass | L15: Conversion Test | M15: Pass | N15: =IF(AND(G15="Pass",K15="Pass",M15="Pass"),"PASS","FAIL") -> PASS | O15: =IF(N15="PASS","Release to practicum","Quarantine — do not issue to students") -> Release to practicum
A16: 9 | B16: MOD-4-20mA | C16: 4-20mA Transmitter | D16: LOT-A-556 | E16: 07-Apr-2026 | F16: 20 | G16: Pass | H16: 20 | I16: 18.77 | J16: Zero @4mA | K16: =IF(G16="Fail","Fail",IF(ABS(I16-H16)/IF(H16=0,1,H16)<=0.1,"Pass","Fail")) -> Pass | L16: Span @20mA | M16: Fail | N16: =IF(AND(G16="Pass",K16="Pass",M16="Pass"),"PASS","FAIL") -> FAIL | O16: =IF(N16="PASS","Release to practicum","Quarantine — do not issue to students") -> Quarantine — do not issue to students
A17: 10 | B17: XDCR-K-TC | C17: K-Type Thermocouple | D17: LOT-A-881 | E17: 07-Apr-2026 | F17: 21 | G17: Pass | H17: 2.5 | I17: 2.36 | J17: Output @25°C | K17: =IF(G17="Fail","Fail",IF(ABS(I17-H17)/IF(H17=0,1,H17)<=0.1,"Pass","Fail")) -> Pass | L17: Insulation Test | M17: Fail | N17: =IF(AND(G17="Pass",K17="Pass",M17="Pass"),"PASS","FAIL") -> FAIL | O17: =IF(N17="PASS","Release to practicum","Quarantine — do not issue to students") -> Quarantine — do not issue to students
A18: 11 | B18: XDCR-PT100 | C18: RTD PT100 | D18: LOT-A-475 | E18: 07-Apr-2026 | F18: 19 | G18: Pass | H18: 100 | I18: 91.49 | J18: Measured R @RT | K18: =IF(G18="Fail","Fail",IF(ABS(I18-H18)/IF(H18=0,1,H18)<=0.1,"Pass","Fail")) -> Pass | L18: Continuity Test | M18: Pass | N18: =IF(AND(G18="Pass",K18="Pass",M18="Pass"),"PASS","FAIL") -> PASS | O18: =IF(N18="PASS","Release to practicum","Quarantine — do not issue to students") -> Release to practicum
A19: 12 | B19: MOD-OLED | C19: OLED Display 0.96" | D19: LOT-A-570 | E19: 07-Apr-2026 | F19: 19 | G19: Pass | H19: 3.3 | I19: 3.48 | J19: Boot Display Test | K19: =IF(G19="Fail","Fail",IF(ABS(I19-H19)/IF(H19=0,1,H19)<=0.1,"Pass","Fail")) -> Pass | L19: I2C Comm Test | M19: Pass | N19: =IF(AND(G19="Pass",K19="Pass",M19="Pass"),"PASS","FAIL") -> PASS | O19: =IF(N19="PASS","Release to practicum","Quarantine — do not issue to students") -> Release to practicum
A21: Inspection Session: Sesi B — Week 2 | Batch: LOT-B-2025
A22: 1 | B22: SEN-LM35 | C22: Temp Sensor LM35 | D22: LOT-B-940 | E22: 12-Apr-2026 | F22: 21 | G22: Pass | H22: 10 | I22: 9.92 | J22: Output @25°C | K22: =IF(G22="Fail","Fail",IF(ABS(I22-H22)/IF(H22=0,1,H22)<=0.1,"Pass","Fail")) -> Pass | L22: Linearity Test | M22: Pass | N22: =IF(AND(G22="Pass",K22="Pass",M22="Pass"),"PASS","FAIL") -> PASS | O22: =IF(N22="PASS","Release to practicum","Quarantine — do not issue to students") -> Release to practicum
A23: 2 | B23: SEN-DS18B20 | C23: 1-Wire Temp Sensor | D23: LOT-B-336 | E23: 12-Apr-2026 | F23: 19 | G23: Pass | H23: 0.5 | I23: 0.49 | J23: Measured Err | K23: =IF(G23="Fail","Fail",IF(ABS(I23-H23)/IF(H23=0,1,H23)<=0.1,"Pass","Fail")) -> Pass | L23: Communication Test | M23: Pass | N23: =IF(AND(G23="Pass",K23="Pass",M23="Pass"),"PASS","FAIL") -> PASS | O23: =IF(N23="PASS","Release to practicum","Quarantine — do not issue to students") -> Release to practicum
A24: 3 | B24: SEN-BMP180 | C24: Pressure Sensor | D24: LOT-B-888 | E24: 12-Apr-2026 | F24: 22 | G24: Pass | H24: 1 | I24: 1.06 | J24: Measured Err | K24: =IF(G24="Fail","Fail",IF(ABS(I24-H24)/IF(H24=0,1,H24)<=0.1,"Pass","Fail")) -> Pass | L24: I2C Comm Test | M24: Pass | N24: =IF(AND(G24="Pass",K24="Pass",M24="Pass"),"PASS","FAIL") -> PASS | O24: =IF(N24="PASS","Release to practicum","Quarantine — do not issue to students") -> Release to practicum
A25: 4 | B25: SEN-LDR | C25: LDR Photo Sensor | D25: LOT-B-943 | E25: 12-Apr-2026 | F25: 20 | G25: Pass | H25: 10 | I25: 10.93 | J25: Dark R Meas | K25: =IF(G25="Fail","Fail",IF(ABS(I25-H25)/IF(H25=0,1,H25)<=0.1,"Pass","Fail")) -> Pass | L25: Light Response Test | M25: Pass | N25: =IF(AND(G25="Pass",K25="Pass",M25="Pass"),"PASS","FAIL") -> PASS | O25: =IF(N25="PASS","Release to practicum","Quarantine — do not issue to students") -> Release to practicum
A26: 5 | B26: SEN-PIR-HC | C26: PIR Motion Sensor | D26: LOT-B-348 | E26: 13-Apr-2026 | F26: 20 | G26: Pass | H26: 5 | I26: 4.64 | J26: Trigger Test | K26: =IF(G26="Fail","Fail",IF(ABS(I26-H26)/IF(H26=0,1,H26)<=0.1,"Pass","Fail")) -> Pass | L26: Detection Range | M26: Pass | N26: =IF(AND(G26="Pass",K26="Pass",M26="Pass"),"PASS","FAIL") -> PASS | O26: =IF(N26="PASS","Release to practicum","Quarantine — do not issue to students") -> Release to practicum
A27: 6 | B27: SEN-US-HC04 | C27: Ultrasonic HC-SR04 | D27: LOT-B-382 | E27: 13-Apr-2026 | F27: 24 | G27: Pass | H27: 400 | I27: 439.53 | J27: Accuracy | K27: =IF(G27="Fail","Fail",IF(ABS(I27-H27)/IF(H27=0,1,H27)<=0.1,"Pass","Fail")) -> Pass | L27: Echo Response Test | M27: Pass | N27: =IF(AND(G27="Pass",K27="Pass",M27="Pass"),"PASS","FAIL") -> PASS | O27: =IF(N27="PASS","Release to practicum","Quarantine — do not issue to students") -> Release to practicum
A28: 7 | B28: MOD-ESP32 | C28: ESP32 MCU Module | D28: LOT-B-508 | E28: 13-Apr-2026 | F28: 19 | G28: Pass | H28: 3.3 | I28: 3.03 | J28: Boot Test | K28: =IF(G28="Fail","Fail",IF(ABS(I28-H28)/IF(H28=0,1,H28)<=0.1,"Pass","Fail")) -> Pass | L28: GPIO Continuity | M28: Pass | N28: =IF(AND(G28="Pass",K28="Pass",M28="Pass"),"PASS","FAIL") -> PASS | O28: =IF(N28="PASS","Release to practicum","Quarantine — do not issue to students") -> Release to practicum
A29: 8 | B29: MOD-ADS1115 | C29: ADC Module 16-bit | D29: LOT-B-845 | E29: 13-Apr-2026 | F29: 19 | G29: Pass | H29: 3.3 | I29: 3.11 | J29: I2C Comm Test | K29: =IF(G29="Fail","Fail",IF(ABS(I29-H29)/IF(H29=0,1,H29)<=0.1,"Pass","Fail")) -> Pass | L29: Conversion Test | M29: Pass | N29: =IF(AND(G29="Pass",K29="Pass",M29="Pass"),"PASS","FAIL") -> PASS | O29: =IF(N29="PASS","Release to practicum","Quarantine — do not issue to students") -> Release to practicum
A30: 9 | B30: MOD-4-20mA | C30: 4-20mA Transmitter | D30: LOT-B-746 | E30: 14-Apr-2026 | F30: 21 | G30: Pass | H30: 20 | I30: 17.99 | J30: Zero @4mA | K30: =IF(G30="Fail","Fail",IF(ABS(I30-H30)/IF(H30=0,1,H30)<=0.1,"Pass","Fail")) -> Fail | L30: Span @20mA | M30: Pass | N30: =IF(AND(G30="Pass",K30="Pass",M30="Pass"),"PASS","FAIL") -> FAIL | O30: =IF(N30="PASS","Release to practicum","Quarantine — do not issue to students") -> Quarantine — do not issue to students
A31: 10 | B31: XDCR-K-TC | C31: K-Type Thermocouple | D31: LOT-B-228 | E31: 14-Apr-2026 | F31: 24 | G31: Pass | H31: 2.5 | I31: 2.68 | J31: Output @25°C | K31: =IF(G31="Fail","Fail",IF(ABS(I31-H31)/IF(H31=0,1,H31)<=0.1,"Pass","Fail")) -> Pass | L31: Insulation Test | M31: Pass | N31: =IF(AND(G31="Pass",K31="Pass",M31="Pass"),"PASS","FAIL") -> PASS | O31: =IF(N31="PASS","Release to practicum","Quarantine — do not issue to students") -> Release to practicum
A32: 11 | B32: XDCR-PT100 | C32: RTD PT100 | D32: LOT-B-576 | E32: 14-Apr-2026 | F32: 25 | G32: Pass | H32: 100 | I32: 101.54 | J32: Measured R @RT | K32: =IF(G32="Fail","Fail",IF(ABS(I32-H32)/IF(H32=0,1,H32)<=0.1,"Pass","Fail")) -> Pass | L32: Continuity Test | M32: Pass | N32: =IF(AND(G32="Pass",K32="Pass",M32="Pass"),"PASS","FAIL") -> PASS | O32: =IF(N32="PASS","Release to practicum","Quarantine — do not issue to students") -> Release to practicum
A33: 12 | B33: MOD-OLED | C33: OLED Display 0.96" | D33: LOT-B-598 | E33: 14-Apr-2026 | F33: 21 | G33: Pass | H33: 3.3 | I33: 3.36 | J33: Boot Display Test | K33: =IF(G33="Fail","Fail",IF(ABS(I33-H33)/IF(H33=0,1,H33)<=0.1,"Pass","Fail")) -> Pass | L33: I2C Comm Test | M33: Pass | N33: =IF(AND(G33="Pass",K33="Pass",M33="Pass"),"PASS","FAIL") -> PASS | O33: =IF(N33="PASS","Release to practicum","Quarantine — do not issue to students") -> Release to practicum
A35: Inspection Session: Sesi C — Week 3 | Batch: LOT-C-2026
A36: 1 | B36: SEN-LM35 | C36: Temp Sensor LM35 | D36: LOT-C-960 | E36: 19-Apr-2026 | F36: 24 | G36: Pass | H36: 10 | I36: 9.33 | J36: Output @25°C | K36: =IF(G36="Fail","Fail",IF(ABS(I36-H36)/IF(H36=0,1,H36)<=0.1,"Pass","Fail")) -> Pass | L36: Linearity Test | M36: Pass | N36: =IF(AND(G36="Pass",K36="Pass",M36="Pass"),"PASS","FAIL") -> PASS | O36: =IF(N36="PASS","Release to practicum","Quarantine — do not issue to students") -> Release to practicum
A37: 2 | B37: SEN-DS18B20 | C37: 1-Wire Temp Sensor | D37: LOT-C-127 | E37: 19-Apr-2026 | F37: 22 | G37: Pass | H37: 0.5 | I37: 0.53 | J37: Measured Err | K37: =IF(G37="Fail","Fail",IF(ABS(I37-H37)/IF(H37=0,1,H37)<=0.1,"Pass","Fail")) -> Pass | L37: Communication Test | M37: Pass | N37: =IF(AND(G37="Pass",K37="Pass",M37="Pass"),"PASS","FAIL") -> PASS | O37: =IF(N37="PASS","Release to practicum","Quarantine — do not issue to students") -> Release to practicum
A38: 3 | B38: SEN-BMP180 | C38: Pressure Sensor | D38: LOT-C-861 | E38: 19-Apr-2026 | F38: 22 | G38: Pass | H38: 1 | I38: 1.05 | J38: Measured Err | K38: =IF(G38="Fail","Fail",IF(ABS(I38-H38)/IF(H38=0,1,H38)<=0.1,"Pass","Fail")) -> Pass | L38: I2C Comm Test | M38: Pass | N38: =IF(AND(G38="Pass",K38="Pass",M38="Pass"),"PASS","FAIL") -> PASS | O38: =IF(N38="PASS","Release to practicum","Quarantine — do not issue to students") -> Release to practicum
A39: 4 | B39: SEN-LDR | C39: LDR Photo Sensor | D39: LOT-C-336 | E39: 19-Apr-2026 | F39: 25 | G39: Pass | H39: 10 | I39: 10.35 | J39: Dark R Meas | K39: =IF(G39="Fail","Fail",IF(ABS(I39-H39)/IF(H39=0,1,H39)<=0.1,"Pass","Fail")) -> Pass | L39: Light Response Test | M39: Pass | N39: =IF(AND(G39="Pass",K39="Pass",M39="Pass"),"PASS","FAIL") -> PASS | O39: =IF(N39="PASS","Release to practicum","Quarantine — do not issue to students") -> Release to practicum
A40: 5 | B40: SEN-PIR-HC | C40: PIR Motion Sensor | D40: LOT-C-453 | E40: 20-Apr-2026 | F40: 22 | G40: Pass | H40: 5 | I40: 5.24 | J40: Trigger Test | K40: =IF(G40="Fail","Fail",IF(ABS(I40-H40)/IF(H40=0,1,H40)<=0.1,"Pass","Fail")) -> Pass | L40: Detection Range | M40: Pass | N40: =IF(AND(G40="Pass",K40="Pass",M40="Pass"),"PASS","FAIL") -> PASS | O40: =IF(N40="PASS","Release to practicum","Quarantine — do not issue to students") -> Release to practicum
A41: 6 | B41: SEN-US-HC04 | C41: Ultrasonic HC-SR04 | D41: LOT-C-445 | E41: 20-Apr-2026 | F41: 25 | G41: Pass | H41: 400 | I41: 444.43 | J41: Accuracy | K41: =IF(G41="Fail","Fail",IF(ABS(I41-H41)/IF(H41=0,1,H41)<=0.1,"Pass","Fail")) -> Fail | L41: Echo Response Test | M41: Pass | N41: =IF(AND(G41="Pass",K41="Pass",M41="Pass"),"PASS","FAIL") -> FAIL | O41: =IF(N41="PASS","Release to practicum","Quarantine — do not issue to students") -> Quarantine — do not issue to students
A42: 7 | B42: MOD-ESP32 | C42: ESP32 MCU Module | D42: LOT-C-308 | E42: 20-Apr-2026 | F42: 19 | G42: Pass | H42: 3.3 | I42: 3.25 | J42: Boot Test | K42: =IF(G42="Fail","Fail",IF(ABS(I42-H42)/IF(H42=0,1,H42)<=0.1,"Pass","Fail")) -> Pass | L42: GPIO Continuity | M42: Pass | N42: =IF(AND(G42="Pass",K42="Pass",M42="Pass"),"PASS","FAIL") -> PASS | O42: =IF(N42="PASS","Release to practicum","Quarantine — do not issue to students") -> Release to practicum
A43: 8 | B43: MOD-ADS1115 | C43: ADC Module 16-bit | D43: LOT-C-249 | E43: 20-Apr-2026 | F43: 23 | G43: Pass | H43: 3.3 | I43: 3.35 | J43: I2C Comm Test | K43: =IF(G43="Fail","Fail",IF(ABS(I43-H43)/IF(H43=0,1,H43)<=0.1,"Pass","Fail")) -> Pass | L43: Conversion Test | M43: Pass | N43: =IF(AND(G43="Pass",K43="Pass",M43="Pass"),"PASS","FAIL") -> PASS | O43: =IF(N43="PASS","Release to practicum","Quarantine — do not issue to students") -> Release to practicum
...

Sheet Jar_Komunikasi
A1: PRAKTIKUM JARINGAN KOMUNIKASI — COMPONENT QC INSPECTION LOG
A2: Lab Sensor & Sistem Telekontrol (SSTK) | Dept. Teknik Nuklir & Teknik Fisika, UGM | ~20 Mahasiswa/Sesi
A3: Test Equipment: Multimeter (Sanwa CD771), DC Power Supply, Spectrum Analyzer (basic), Serial Terminal (Arduino IDE), Oscilloscope
A5: No. | B5: Part Number | C5: Component Description | D5: Batch / Lot No. | E5: Inspection Date | F5: Qty | G5: Visual Inspection | H5: Spec / Rated Value | I5: Measured Value | J5: Functional Test 1 | K5: Test 1 Result | L5: Functional Test 2 | M5: Test 2 Result | N5: Overall Result | O5: Remarks / Disposition
A6: ⚠ Columns shaded yellow = manual input per inspection session | Columns shaded gray = auto-calculated by formula | Overall Result = auto (PASS only if ALL tests pass)
A7: Inspection Session: Sesi A — Week 1 | Batch: LOT-A-2024
A8: 1 | B8: MOD-NRF24L01 | C8: RF Module 2.4GHz | D8: LOT-A-785 | E8: 05-Apr-2026 | F8: 18 | G8: Pass | H8: 3.3 | I8: 3.05 | J8: Power Test | K8: =IF(G8="Fail","Fail",IF(ABS(I8-H8)/IF(H8=0,1,H8)<=0.1,"Pass","Fail")) -> Pass | L8: TX/RX Comm Test | M8: Pass | N8: =IF(AND(G8="Pass",K8="Pass",M8="Pass"),"PASS","FAIL") -> PASS | O8: =IF(N8="PASS","Release to practicum","Quarantine — do not issue to students") -> Release to practicum
A9: 2 | B9: MOD-HC-05 | C9: Bluetooth Module | D9: LOT-A-407 | E9: 05-Apr-2026 | F9: 21 | G9: Pass | H9: 5 | I9: 5.24 | J9: AT Cmd Response | K9: =IF(G9="Fail","Fail",IF(ABS(I9-H9)/IF(H9=0,1,H9)<=0.1,"Pass","Fail")) -> Pass | L9: Pairing Test | M9: Pass | N9: =IF(AND(G9="Pass",K9="Pass",M9="Pass"),"PASS","FAIL") -> PASS | O9: =IF(N9="PASS","Release to practicum","Quarantine — do not issue to students") -> Release to practicum
A10: 3 | B10: MOD-SIM800L | C10: GSM/GPRS Module | D10: LOT-A-608 | E10: 05-Apr-2026 | F10: 18 | G10: Pass | H10: 4 | I10: 4.17 | J10: AT Cmd Response | K10: =IF(G10="Fail","Fail",IF(ABS(I10-H10)/IF(H10=0,1,H10)<=0.1,"Pass","Fail")) -> Pass | L10: SIM Card Detection | M10: Pass | N10: =IF(AND(G10="Pass",K10="Pass",M10="Pass"),"PASS","FAIL") -> PASS | O10: =IF(N10="PASS","Release to practicum","Quarantine — do not issue to students") -> Release to practicum
A11: 4 | B11: MOD-LORA32 | C11: LoRa Module 433MHz | D11: LOT-A-761 | E11: 05-Apr-2026 | F11: 21 | G11: Fail | H11: 3.3 | I11: 3.08 | J11: TX Power | K11: =IF(G11="Fail","Fail",IF(ABS(I11-H11)/IF(H11=0,1,H11)<=0.1,"Pass","Fail")) -> Fail | L11: RX Sensitivity | M11: Pass | N11: =IF(AND(G11="Pass",K11="Pass",M11="Pass"),"PASS","FAIL") -> FAIL | O11: =IF(N11="PASS","Release to practicum","Quarantine — do not issue to students") -> Quarantine — do not issue to students
A12: 5 | B12: MOD-MAX485 | C12: RS-485 Transceiver | D12: LOT-A-742 | E12: 06-Apr-2026 | F12: 21 | G12: Pass | H12: 5 | I12: 5.09 | J12: Power Test | K12: =IF(G12="Fail","Fail",IF(ABS(I12-H12)/IF(H12=0,1,H12)<=0.1,"Pass","Fail")) -> Pass | L12: Tx/Rx Enable Test | M12: Pass | N12: =IF(AND(G12="Pass",K12="Pass",M12="Pass"),"PASS","FAIL") -> PASS | O12: =IF(N12="PASS","Release to practicum","Quarantine — do not issue to students") -> Release to practicum
A13: 6 | B13: MOD-MCP2515 | C13: CAN Bus Controller | D13: LOT-A-604 | E13: 06-Apr-2026 | F13: 20 | G13: Pass | H13: 5 | I13: 4.98 | J13: SPI Comm Test | K13: =IF(G13="Fail","Fail",IF(ABS(I13-H13)/IF(H13=0,1,H13)<=0.1,"Pass","Fail")) -> Pass | L13: CAN Frame Test | M13: Pass | N13: =IF(AND(G13="Pass",K13="Pass",M13="Pass"),"PASS","FAIL") -> PASS | O13: =IF(N13="PASS","Release to practicum","Quarantine — do not issue to students") -> Release to practicum
A14: 7 | B14: CON-RJ45 | C14: RJ45 Connector Cat5e | D14: LOT-A-748 | E14: 06-Apr-2026 | F14: 25 | G14: Pass | H14: 8 | I14: 7.14 | J14: Continuity | K14: =IF(G14="Fail","Fail",IF(ABS(I14-H14)/IF(H14=0,1,H14)<=0.1,"Pass","Fail")) -> Fail | L14: Crimp Quality | M14: Pass | N14: =IF(AND(G14="Pass",K14="Pass",M14="Pass"),"PASS","FAIL") -> FAIL | O14: =IF(N14="PASS","Release to practicum","Quarantine — do not issue to students") -> Quarantine — do not issue to students
A15: 8 | B15: CBL-USB-A | C15: USB-A to USB-B 1m | D15: LOT-A-763 | E15: 06-Apr-2026 | F15: 20 | G15: Pass | H15: 4 | I15: 3.94 | J15: Pin Continuity | K15: =IF(G15="Fail","Fail",IF(ABS(I15-H15)/IF(H15=0,1,H15)<=0.1,"Pass","Fail")) -> Pass | L15: Data Transfer Test | M15: Fail | N15: =IF(AND(G15="Pass",K15="Pass",M15="Pass"),"PASS","FAIL") -> FAIL | O15: =IF(N15="PASS","Release to practicum","Quarantine — do not issue to students") -> Quarantine — do not issue to students
A16: 9 | B16: REL-G5V-DC5 | C16: Signal Relay 5VDC | D16: LOT-A-421 | E16: 07-Apr-2026 | F16: 20 | G16: Pass | H16: 50 | I16: 52.03 | J16: Coil R Meas | K16: =IF(G16="Fail","Fail",IF(ABS(I16-H16)/IF(H16=0,1,H16)<=0.1,"Pass","Fail")) -> Pass | L16: Switching Test | M16: Pass | N16: =IF(AND(G16="Pass",K16="Pass",M16="Pass"),"PASS","FAIL") -> PASS | O16: =IF(N16="PASS","Release to practicum","Quarantine — do not issue to students") -> Release to practicum
A17: 10 | B17: ANT-2.4G | C17: 2.4GHz PCB Antenna | D17: LOT-A-938 | E17: 07-Apr-2026 | F17: 23 | G17: Pass | H17: 2 | I17: 2.05 | J17: Connector Check | K17: =IF(G17="Fail","Fail",IF(ABS(I17-H17)/IF(H17=0,1,H17)<=0.1,"Pass","Fail")) -> Pass | L17: Return Loss Test | M17: Pass | N17: =IF(AND(G17="Pass",K17="Pass",M17="Pass"),"PASS","FAIL") -> PASS | O17: =IF(N17="PASS","Release to practicum","Quarantine — do not issue to students") -> Release to practicum
A18: 11 | B18: TB-2P-5MM | C18: Terminal Block 2P | D18: LOT-A-609 | E18: 07-Apr-2026 | F18: 24 | G18: Pass | H18: 10 | I18: 8.84 | J18: Contact R | K18: =IF(G18="Fail","Fail",IF(ABS(I18-H18)/IF(H18=0,1,H18)<=0.1,"Pass","Fail")) -> Fail | L18: Screw Torque Test | M18: Pass | N18: =IF(AND(G18="Pass",K18="Pass",M18="Pass"),"PASS","FAIL") -> FAIL | O18: =IF(N18="PASS","Release to practicum","Quarantine — do not issue to students") -> Quarantine — do not issue to students
A19: 12 | B19: TB-3P-5MM | C19: Terminal Block 3P | D19: LOT-A-483 | E19: 07-Apr-2026 | F19: 23 | G19: Pass | H19: 10 | I19: 9.72 | J19: Contact R | K19: =IF(G19="Fail","Fail",IF(ABS(I19-H19)/IF(H19=0,1,H19)<=0.1,"Pass","Fail")) -> Pass | L19: Screw Torque Test | M19: Pass | N19: =IF(AND(G19="Pass",K19="Pass",M19="Pass"),"PASS","FAIL") -> PASS | O19: =IF(N19="PASS","Release to practicum","Quarantine — do not issue to students") -> Release to practicum
A21: Inspection Session: Sesi B — Week 2 | Batch: LOT-B-2025
A22: 1 | B22: MOD-NRF24L01 | C22: RF Module 2.4GHz | D22: LOT-B-714 | E22: 12-Apr-2026 | F22: 21 | G22: Pass | H22: 3.3 | I22: 3.69 | J22: Power Test | K22: =IF(G22="Fail","Fail",IF(ABS(I22-H22)/IF(H22=0,1,H22)<=0.1,"Pass","Fail")) -> Fail | L22: TX/RX Comm Test | M22: Pass | N22: =IF(AND(G22="Pass",K22="Pass",M22="Pass"),"PASS","FAIL") -> FAIL | O22: =IF(N22="PASS","Release to practicum","Quarantine — do not issue to students") -> Quarantine — do not issue to students
A23: 2 | B23: MOD-HC-05 | C23: Bluetooth Module | D23: LOT-B-774 | E23: 12-Apr-2026 | F23: 18 | G23: Pass | H23: 5 | I23: 5.27 | J23: AT Cmd Response | K23: =IF(G23="Fail","Fail",IF(ABS(I23-H23)/IF(H23=0,1,H23)<=0.1,"Pass","Fail")) -> Pass | L23: Pairing Test | M23: Pass | N23: =IF(AND(G23="Pass",K23="Pass",M23="Pass"),"PASS","FAIL") -> PASS | O23: =IF(N23="PASS","Release to practicum","Quarantine — do not issue to students") -> Release to practicum
A24: 3 | B24: MOD-SIM800L | C24: GSM/GPRS Module | D24: LOT-B-592 | E24: 12-Apr-2026 | F24: 18 | G24: Pass | H24: 4 | I24: 3.92 | J24: AT Cmd Response | K24: =IF(G24="Fail","Fail",IF(ABS(I24-H24)/IF(H24=0,1,H24)<=0.1,"Pass","Fail")) -> Pass | L24: SIM Card Detection | M24: Pass | N24: =IF(AND(G24="Pass",K24="Pass",M24="Pass"),"PASS","FAIL") -> PASS | O24: =IF(N24="PASS","Release to practicum","Quarantine — do not issue to students") -> Release to practicum
A25: 4 | B25: MOD-LORA32 | C25: LoRa Module 433MHz | D25: LOT-B-385 | E25: 12-Apr-2026 | F25: 18 | G25: Fail | H25: 3.3 | I25: 3.62 | J25: TX Power | K25: =IF(G25="Fail","Fail",IF(ABS(I25-H25)/IF(H25=0,1,H25)<=0.1,"Pass","Fail")) -> Fail | L25: RX Sensitivity | M25: Pass | N25: =IF(AND(G25="Pass",K25="Pass",M25="Pass"),"PASS","FAIL") -> FAIL | O25: =IF(N25="PASS","Release to practicum","Quarantine — do not issue to students") -> Quarantine — do not issue to students
A26: 5 | B26: MOD-MAX485 | C26: RS-485 Transceiver | D26: LOT-B-993 | E26: 13-Apr-2026 | F26: 25 | G26: Pass | H26: 5 | I26: 4.63 | J26: Power Test | K26: =IF(G26="Fail","Fail",IF(ABS(I26-H26)/IF(H26=0,1,H26)<=0.1,"Pass","Fail")) -> Pass | L26: Tx/Rx Enable Test | M26: Pass | N26: =IF(AND(G26="Pass",K26="Pass",M26="Pass"),"PASS","FAIL") -> PASS | O26: =IF(N26="PASS","Release to practicum","Quarantine — do not issue to students") -> Release to practicum
A27: 6 | B27: MOD-MCP2515 | C27: CAN Bus Controller | D27: LOT-B-285 | E27: 13-Apr-2026 | F27: 19 | G27: Pass | H27: 5 | I27: 5 | J27: SPI Comm Test | K27: =IF(G27="Fail","Fail",IF(ABS(I27-H27)/IF(H27=0,1,H27)<=0.1,"Pass","Fail")) -> Pass | L27: CAN Frame Test | M27: Fail | N27: =IF(AND(G27="Pass",K27="Pass",M27="Pass"),"PASS","FAIL") -> FAIL | O27: =IF(N27="PASS","Release to practicum","Quarantine — do not issue to students") -> Quarantine — do not issue to students
A28: 7 | B28: CON-RJ45 | C28: RJ45 Connector Cat5e | D28: LOT-B-200 | E28: 13-Apr-2026 | F28: 22 | G28: Fail | H28: 8 | I28: 7.98 | J28: Continuity | K28: =IF(G28="Fail","Fail",IF(ABS(I28-H28)/IF(H28=0,1,H28)<=0.1,"Pass","Fail")) -> Fail | L28: Crimp Quality | M28: Fail | N28: =IF(AND(G28="Pass",K28="Pass",M28="Pass"),"PASS","FAIL") -> FAIL | O28: =IF(N28="PASS","Release to practicum","Quarantine — do not issue to students") -> Quarantine — do not issue to students
A29: 8 | B29: CBL-USB-A | C29: USB-A to USB-B 1m | D29: LOT-B-892 | E29: 13-Apr-2026 | F29: 18 | G29: Pass | H29: 4 | I29: 3.88 | J29: Pin Continuity | K29: =IF(G29="Fail","Fail",IF(ABS(I29-H29)/IF(H29=0,1,H29)<=0.1,"Pass","Fail")) -> Pass | L29: Data Transfer Test | M29: Pass | N29: =IF(AND(G29="Pass",K29="Pass",M29="Pass"),"PASS","FAIL") -> PASS | O29: =IF(N29="PASS","Release to practicum","Quarantine — do not issue to students") -> Release to practicum
